<?xml version="1.0" encoding="utf-8"?>
<!-- This URDF was automatically created by SolidWorks to URDF Exporter! Originally created by Stephen Brawner (brawner@gmail.com) 
     Commit Version: 1.6.0-4-g7f85cfe  Build Version: 1.6.7995.38578
     For more information, please see http://wiki.ros.org/sw_urdf_exporter -->
<robot
  name="bras_robot_kone">
  <link
    name="base_link">
    <inertial>
      <origin
        xyz="-0.0439390916743305 -0.00824743509828847 0.0750001368355614"
        rpy="0 0 0" />
      <mass
        value="1.15616260183108" />
      <inertia
        ixx="0.00201252660466385"
        ixy="-5.84389314167828E-11"
        ixz="1.15648471369529E-09"
        iyy="0.00254071599730866"
        iyz="-9.2583283272325E-10"
        izz="0.00201252366056206" />
    </inertial>
    <visual>
      <origin
        xyz="0 0 0"
        rpy="0 0 0" />
      <geometry>
        <mesh
          filename="package://bras_robot_kone/meshes/base_link.STL" />
      </geometry>
      <material
        name="">
        <color
          rgba="0.792156862745098 0.819607843137255 0.933333333333333 1" />
      </material>
    </visual>
    <collision>
      <origin
        xyz="0 0 0"
        rpy="0 0 0" />
      <geometry>
        <mesh
          filename="package://bras_robot_kone/meshes/base_link.STL" />
      </geometry>
    </collision>
  </link>
  <link
    name="link_1">
    <inertial>
      <origin
        xyz="-3.1782E-08 0.039149 0.0038439"
        rpy="0 0 0" />
      <mass
        value="0.28935" />
      <inertia
        ixx="0.00023422"
        ixy="-5.2518E-11"
        ixz="2.1705E-10"
        iyy="0.00017347"
        iyz="-3.0518E-06"
        izz="0.00021948" />
    </inertial>
    <visual>
      <origin
        xyz="0 0 0"
        rpy="0 0 0" />
      <geometry>
        <mesh
          filename="package://bras_robot_kone/meshes/link_1.STL" />
      </geometry>
      <material
        name="">
        <color
          rgba="0.79216 0.81961 0.93333 1" />
      </material>
    </visual>
    <collision>
      <origin
        xyz="0 0 0"
        rpy="0 0 0" />
      <geometry>
        <mesh
          filename="package://bras_robot_kone/meshes/link_1.STL" />
      </geometry>
    </collision>
  </link>
  <joint
    name="joint0"
    type="revolute">
    <origin
      xyz="-0.043939 -0.075 0.075658"
      rpy="1.5708 0 1.7893" />
    <parent
      link="base_link" />
    <child
      link="link_1" />
    <axis
      xyz="0 1 0" />
    <limit
      lower="-1.57"
      upper="1.57"
      effort="10"
      velocity="100" />
  </joint>
  <link
    name="link_2">
    <inertial>
      <origin
        xyz="2.35405509894093E-05 0.0356351701817949 0.0538201047690854"
        rpy="0 0 0" />
      <mass
        value="0.531525546414824" />
      <inertia
        ixx="0.000823332325834598"
        ixy="4.77518531309744E-07"
        ixz="4.3876184733731E-08"
        iyy="0.000759809477216489"
        iyz="-3.3136942033293E-06"
        izz="0.000292449829863382" />
    </inertial>
    <visual>
      <origin
        xyz="0 0 0"
        rpy="0 0 0" />
      <geometry>
        <mesh
          filename="package://bras_robot_kone/meshes/link_2.STL" />
      </geometry>
      <material
        name="">
        <color
          rgba="0.792156862745098 0.819607843137255 0.933333333333333 1" />
      </material>
    </visual>
    <collision>
      <origin
        xyz="0 0 0"
        rpy="0 0 0" />
      <geometry>
        <mesh
          filename="package://bras_robot_kone/meshes/link_2.STL" />
      </geometry>
    </collision>
  </link>
  <joint
    name="joint1"
    type="revolute">
    <origin
      xyz="0 0.04 0.041261"
      rpy="1.5708 0 -3.0383" />
    <parent
      link="link_1" />
    <child
      link="link_2" />
    <axis
      xyz="0 1 0" />
    <limit
      lower="-1.57"
      upper="1.57"
      effort="10"
      velocity="100" />
  </joint>
  <link
    name="link_3">
    <inertial>
      <origin
        xyz="-1.48692601287248E-08 -0.000850596874469905 -0.0421039527998203"
        rpy="0 0 0" />
      <mass
        value="0.289351676799976" />
      <inertia
        ixx="0.000234216248202112"
        ixy="-6.29449176223973E-11"
        ixz="1.73502015400997E-10"
        iyy="0.00017347323078365"
        iyz="-3.05178708302161E-06"
        izz="0.000219481401320033" />
    </inertial>
    <visual>
      <origin
        xyz="0 0 0"
        rpy="0 0 0" />
      <geometry>
        <mesh
          filename="package://bras_robot_kone/meshes/link_3.STL" />
      </geometry>
      <material
        name="">
        <color
          rgba="0.792156862745098 0.819607843137255 0.933333333333333 1" />
      </material>
    </visual>
    <collision>
      <origin
        xyz="0 0 0"
        rpy="0 0 0" />
      <geometry>
        <mesh
          filename="package://bras_robot_kone/meshes/link_3.STL" />
      </geometry>
    </collision>
  </link>
  <joint
    name="joint2"
    type="revolute">
    <origin
      xyz="0 0.036239 0.18105"
      rpy="3.1416 0 2.9025" />
    <parent
      link="link_2" />
    <child
      link="link_3" />
    <axis
      xyz="0 0 1" />
    <limit
      lower="-1.57"
      upper="1.57"
      effort="10"
      velocity="100" />
  </joint>
  <link
    name="link_4">
    <inertial>
      <origin
        xyz="-0.000123969521874143 0.0444911830931757 0.053820109475482"
        rpy="0 0 0" />
      <mass
        value="0.531525516642012" />
      <inertia
        ixx="0.000821207170459937"
        ixy="-1.27260927942252E-06"
        ixz="-2.29868804648989E-07"
        iyy="0.000761934526799435"
        iyz="-3.18449437904773E-06"
        izz="0.000292449840197185" />
    </inertial>
    <visual>
      <origin
        xyz="0 0 0"
        rpy="0 0 0" />
      <geometry>
        <mesh
          filename="package://bras_robot_kone/meshes/link_4.STL" />
      </geometry>
      <material
        name="">
        <color
          rgba="0.792156862745098 0.819607843137255 0.933333333333333 1" />
      </material>
    </visual>
    <collision>
      <origin
        xyz="0 0 0"
        rpy="0 0 0" />
      <geometry>
        <mesh
          filename="package://bras_robot_kone/meshes/link_4.STL" />
      </geometry>
    </collision>
  </link>
  <joint
    name="joint3"
    type="revolute">
    <origin
      xyz="0 -0.034974 -0.045948"
      rpy="-3.1416 -0.12953 0" />
    <parent
      link="link_3" />
    <child
      link="link_4" />
    <axis
      xyz="0 1 0" />
    <limit
      lower="-1.57"
      upper="1.57"
      effort="10"
      velocity="100" />
  </joint>
  <link
    name="link_5">
    <inertial>
      <origin
        xyz="1.08240438001506E-08 -0.0008505990230291 -0.0355404466306268"
        rpy="0 0 0" />
      <mass
        value="0.28935163226641" />
      <inertia
        ixx="0.0002342161761347"
        ixy="-8.83565338407298E-11"
        ixz="8.38072971269063E-11"
        iyy="0.000173473227369963"
        iyz="-3.05177250771006E-06"
        izz="0.000219481412455453" />
    </inertial>
    <visual>
      <origin
        xyz="0 0 0"
        rpy="0 0 0" />
      <geometry>
        <mesh
          filename="package://bras_robot_kone/meshes/link_5.STL" />
      </geometry>
      <material
        name="">
        <color
          rgba="0.792156862745098 0.819607843137255 0.933333333333333 1" />
      </material>
    </visual>
    <collision>
      <origin
        xyz="0 0 0"
        rpy="0 0 0" />
      <geometry>
        <mesh
          filename="package://bras_robot_kone/meshes/link_5.STL" />
      </geometry>
    </collision>
  </link>
  <joint
    name="joint4"
    type="revolute">
    <origin
      xyz="0 0.045026 0.18762"
      rpy="3.1416 0 0.2514" />
    <parent
      link="link_4" />
    <child
      link="link_5" />
    <axis
      xyz="0 0 1" />
    <limit
      lower="-1.57"
      upper="1.57"
      effort="10"
      velocity="100" />
  </joint>
  <link
    name="link_6">
    <inertial>
      <origin
        xyz="-1.53701241734083E-08 0.0329285054868462 0.0038439145067623"
        rpy="0 0 0" />
      <mass
        value="0.289351767797651" />
      <inertia
        ixx="0.00023421648369462"
        ixy="-7.87387063780039E-11"
        ixz="1.29280080666042E-10"
        iyy="0.000173473234158932"
        iyz="-3.05180863708667E-06"
        izz="0.000219481354211361" />
    </inertial>
    <visual>
      <origin
        xyz="0 0 0"
        rpy="0 0 0" />
      <geometry>
        <mesh
          filename="package://bras_robot_kone/meshes/link_6.STL" />
      </geometry>
      <material
        name="">
        <color
          rgba="0.792156862745098 0.819607843137255 0.933333333333333 1" />
      </material>
    </visual>
    <collision>
      <origin
        xyz="0 0 0"
        rpy="0 0 0" />
      <geometry>
        <mesh
          filename="package://bras_robot_kone/meshes/link_6.STL" />
      </geometry>
    </collision>
  </link>
  <joint
    name="joint5"
    type="revolute">
    <origin
      xyz="0 -0.046221 -0.039384"
      rpy="-3.1416 -0.45971 0" />
    <parent
      link="link_5" />
    <child
      link="link_6" />
    <axis
      xyz="0 1 0" />
    <limit
      lower="-1.57"
      upper="1.57"
      effort="10"
      velocity="100" />
  </joint>
  <link
    name="link_7">
    <inertial>
      <origin
        xyz="0.000436939097562219 0.00472174851374407 -1.91344858714304E-05"
        rpy="0 0 0" />
      <mass
        value="0.0578450140794518" />
      <inertia
        ixx="1.70796849535902E-05"
        ixy="1.29079224119903E-07"
        ixz="5.19694801284576E-08"
        iyy="1.58193115885008E-05"
        iyz="-7.86078318786058E-09"
        izz="1.82717567094603E-05" />
    </inertial>
    <visual>
      <origin
        xyz="0 0 0"
        rpy="0 0 0" />
      <geometry>
        <mesh
          filename="package://bras_robot_kone/meshes/link_7.STL" />
      </geometry>
      <material
        name="">
        <color
          rgba="0.792156862745098 0.819607843137255 0.933333333333333 1" />
      </material>
    </visual>
    <collision>
      <origin
        xyz="0 0 0"
        rpy="0 0 0" />
      <geometry>
        <mesh
          filename="package://bras_robot_kone/meshes/link_7.STL" />
      </geometry>
    </collision>
  </link>
  <joint
    name="joint6"
    type="revolute">
    <origin
      xyz="0 0.033779 0.050476"
      rpy="1.5708 0 -2.1909" />
    <parent
      link="link_6" />
    <child
      link="link_7" />
    <axis
      xyz="0 1 0" />
    <limit
      lower="-1.57"
      upper="1.57"
      effort="10"
      velocity="100" />
  </joint>
  <link
    name="end_effector">
    <inertial>
      <origin
        xyz="-1.7990192520051E-05 0.0414428435042036 0.0490901668874435"
        rpy="0 0 0" />
      <mass
        value="0.116085415446928" />
      <inertia
        ixx="5.06173187250878E-05"
        ixy="-2.12626883955172E-07"
        ixz="3.16026596193211E-09"
        iyy="0.000270586101442848"
        iyz="-4.14141570536042E-09"
        izz="0.000317922147797635" />
    </inertial>
    <visual>
      <origin
        xyz="0 0 0"
        rpy="0 0 0" />
      <geometry>
        <mesh
          filename="package://bras_robot_kone/meshes/end_effector.STL" />
      </geometry>
      <material
        name="">
        <color
          rgba="0.792156862745098 0.819607843137255 0.933333333333333 1" />
      </material>
    </visual>
    <collision>
      <origin
        xyz="0 0 0"
        rpy="0 0 0" />
      <geometry>
        <mesh
          filename="package://bras_robot_kone/meshes/end_effector.STL" />
      </geometry>
    </collision>
  </link>
  <joint
    name="end_effector_joint"
    type="fixed">
    <origin
      xyz="0.021919 0 0.035517"
      rpy="-1.5708 0.55293 0" />
    <parent
      link="link_7" />
    <child
      link="end_effector" />
    <axis
      xyz="0 0 1" />
    <limit
      lower="0"
      upper="0"
      effort="0"
      velocity="0" />
  </joint>
</robot>